Workbook

Sheet Overview
I4: Chicago, IL 60631
I5: info@construct.com
I6: construct.com
I7: 222 555 7777
C11: Project Overview
D12: This residential construction budget project involves developing comprehensive budget estimates for Construct Corp's residential construction project in Chicago, IL. The scope of the project includes analyzing construction plans, material costs, labor expenses, and other related factors to provide accurate and cost-effective budget recommendations for clients.
C15: Assumptions and Exclusions
D16: 1. The budget includes all required construction permits and approvals.
D17: 2. The budget excludes costs for architectural or design fees.
D18: 3. Any unforeseen site conditions or changes in the project scope are not accounted for in the budget.
D19: 4. The budget does not include post-renovation cleaning service fees.
D20: 5. The budget excludes any additional fees for landscaping or exterior improvements.

Sheet Residential Construction Budget
N4: Chicago, IL 60631
N5: info@construct.com
N6: construct.com
N7: 222 555 7777
N11: =C14 -> Value Engineering
C12: Residential Construction Budget | N12: =F22 -> 8000
C14: Value Engineering | J14: {=C37:C48} -> Excavation | K14: {=G37:G48} -> 12600
C15: Cost Category | D15: Proposed Alternative | F15: Estimated Cost Savings | J15: Foundation | K15: 11100
C16: Electrical | D16: LED lighting fixtures | F16: 1500 | J16: Framing | K16: 7300 | N16: =C24 -> Budget Summary
C17: Plumbing | D17: Water-efficient fixtures | F17: 2800 | J17: Roofing | K17: 7600 | N17: =F32 -> 18500
C18: HVAC | D18: Energy-efficient HVAC system | F18: 2500 | J18: Plumbing | K18: 7000
C19: Flooring | D19: Waterproof vinyl flooring | F19: 1200 | J19: Electrical | K19: 7800
J20: HVAC | K20: 7000
J21: Insulation | K21: 8400
C22: Total : | F22: =SUM(F16:G19) -> 8000 | J22: Drywall | K22: 12000 | N22: =C35 -> Cost Breakdown Structure
J23: Flooring | K23: 11100 | N23: =G49 -> 91900
C24: Budget Summary | J24: 0 | K24: 0
C25: Category | F25: Estimated Cost Savings | J25: 0 | K25: 0
C26: Total Estimated Cost | F26: 9000
C27: Contingency Costs | F27: 7500
C28: Additional Provisions | F28: 2000 | N28: =J35 -> Cash Flow Projection
N29: =L49 -> 70000
C31: - | F31: -
C32: Total : | F32: =SUM(F26:G28) -> 18500
C35: Cost Breakdown Structure | J35: Cash Flow Projection
C36: Cost Category | D36: Labor | E36: Materials | F36: Equipment | G36: Total | J36: Month | K36: Cash Inflow | L36: Cash Outflow | M36: Remarks
C37: ='Cost Breakdown Structure'!C18 -> Excavation | D37: ='Cost Breakdown Structure'!D18 -> 4300 | E37: ='Cost Breakdown Structure'!D30 -> 4200 | F37: ='Cost Breakdown Structure'!D42 -> 4100 | G37: =SUM(D37:F37) -> 12600 | J37: January | K37: 50000 | L37: - | M37: Initial client payment
C38: ='Cost Breakdown Structure'!C19 -> Foundation | D38: ='Cost Breakdown Structure'!D19 -> 4100 | E38: ='Cost Breakdown Structure'!D31 -> 3500 | F38: ='Cost Breakdown Structure'!D43 -> 3500 | G38: =SUM(D38:F38) -> 11100 | J38: February | K38: - | L38: 15000 | M38: Acquisition of permits and start of the construction project
C39: ='Cost Breakdown Structure'!C20 -> Framing | D39: ='Cost Breakdown Structure'!D20 -> 3800 | E39: ='Cost Breakdown Structure'!D32 -> 0 | F39: ='Cost Breakdown Structure'!D44 -> 3500 | G39: =SUM(D39:F39) -> 7300 | J39: March | K39: - | L39: 13000
C40: ='Cost Breakdown Structure'!C21 -> Roofing | D40: ='Cost Breakdown Structure'!D21 -> 3400 | E40: ='Cost Breakdown Structure'!D33 -> 0 | F40: ='Cost Breakdown Structure'!D45 -> 4200 | G40: =SUM(D40:F40) -> 7600 | J40: April | K40: 20000 | L40: -
C41: ='Cost Breakdown Structure'!C22 -> Plumbing | D41: ='Cost Breakdown Structure'!D22 -> 3500 | E41: ='Cost Breakdown Structure'!D34 -> 0 | F41: ='Cost Breakdown Structure'!D46 -> 3500 | G41: =SUM(D41:F41) -> 7000 | J41: May | K41: - | L41: 10000
C42: ='Cost Breakdown Structure'!C23 -> Electrical | D42: ='Cost Breakdown Structure'!D23 -> 4300 | E42: ='Cost Breakdown Structure'!D35 -> 0 | F42: ='Cost Breakdown Structure'!D47 -> 3500 | G42: =SUM(D42:F42) -> 7800 | J42: June | K42: - | L42: -
C43: ='Cost Breakdown Structure'!C24 -> HVAC | D43: ='Cost Breakdown Structure'!D24 -> 3500 | E43: ='Cost Breakdown Structure'!D36 -> 0 | F43: ='Cost Breakdown Structure'!D48 -> 3500 | G43: =SUM(D43:F43) -> 7000 | J43: July | K43: 20000 | L43: 5000
C44: ='Cost Breakdown Structure'!C25 -> Insulation | D44: ='Cost Breakdown Structure'!D25 -> 3500 | E44: ='Cost Breakdown Structure'!D37 -> 600 | F44: ='Cost Breakdown Structure'!D49 -> 4300 | G44: =SUM(D44:F44) -> 8400 | J44: August | K44: - | L44: 6000
C45: ='Cost Breakdown Structure'!C26 -> Drywall | D45: ='Cost Breakdown Structure'!D26 -> 4200 | E45: ='Cost Breakdown Structure'!D38 -> 4300 | F45: ='Cost Breakdown Structure'!D50 -> 3500 | G45: =SUM(D45:F45) -> 12000 | J45: September | K45: - | L45: 8000
C46: ='Cost Breakdown Structure'!C27 -> Flooring | D46: ='Cost Breakdown Structure'!D27 -> 3500 | E46: ='Cost Breakdown Structure'!D39 -> 3500 | F46: ='Cost Breakdown Structure'!D51 -> 4100 | G46: =SUM(D46:F46) -> 11100 | J46: October | K46: 10000 | L46: 2000
C47: ='Cost Breakdown Structure'!C28 -> 0 | D47: ='Cost Breakdown Structure'!D28 -> 0 | E47: ='Cost Breakdown Structure'!D40 -> 0 | F47: ='Cost Breakdown Structure'!D52 -> 0 | G47: =SUM(D47:F47) -> 0 | J47: November | K47: - | L47: 1000
C48: ='Cost Breakdown Structure'!C28 -> 0 | D48: ='Cost Breakdown Structure'!D28 -> 0 | E48: ='Cost Breakdown Structure'!D40 -> 0 | F48: ='Cost Breakdown Structure'!D52 -> 0 | G48: =SUM(D48:F48) -> 0 | J48: December | K48: - | L48: 10000
C49: Total : | D49: =SUM(D37:D48) -> 38100 | E49: =SUM(E37:E48) -> 16100 | F49: =SUM(F37:F48) -> 37700 | G49: =SUM(G37:G48) -> 91900 | J49: Total : | K49: =SUM(K37:K48) -> 100000 | L49: =SUM(L37:L48) -> 70000

Sheet Cost Breakdown Structure
B2: COST BREAKDOWN STRUCTURE
C4: Date Prepared | E4: 47721
C6: Prepared by | E6: John Mitchell
C8: For the Year | E8: =E4 -> 47721
C12: CATEGORY | D12: {=TRANSPOSE(C18:C28)} -> Excavation | E12: Foundation | F12: Framing | G12: Roofing | H12: Plumbing | I12: Electrical | J12: HVAC | K12: Insulation | L12: Drywall | M12: Flooring | N12: 0 | O12: TOTAL COST
C13: LABOR | D13: {=TRANSPOSE(D18:D28)} -> 4300 | E13: 4100 | F13: 3800 | G13: 3400 | H13: 3500 | I13: 4300 | J13: 3500 | K13: 3500 | L13: 4200 | M13: 3500 | N13: 0 | O13: =SUM(D13:N13) -> 38100
C14: MATERIALS | D14: {=TRANSPOSE(D30:D40)} -> 4200 | E14: 3500 | F14: 0 | G14: 0 | H14: 0 | I14: 0 | J14: 0 | K14: 600 | L14: 4300 | M14: 3500 | N14: 0 | O14: =SUM(D14:N14) -> 16100
C15: EQUIPMENT | D15: {=TRANSPOSE(D42:D52)} -> 4100 | E15: 3500 | F15: 3500 | G15: 4200 | H15: 3500 | I15: 3500 | J15: 3500 | K15: 4300 | L15: 3500 | M15: 4100 | N15: 0 | O15: =SUM(D15:N15) -> 37700
B17: LABOR | C17: Cost Category | D17: TOTAL | E17: 44927 | F17: 44958 | G17: 44986 | H17: 45017 | I17: 45047 | J17: 45078 | K17: 45108 | L17: 45139 | M17: 45170 | N17: 45200 | O17: 45231 | P17: 45261
C18: Excavation | D18: =SUM(E18:P18) -> 4300 | E18: 1000 | F18: 100 | G18: 200 | H18: 300 | I18: 400 | J18: 200 | K18: 100 | L18: 200 | M18: 300 | N18: 400 | O18: 500 | P18: 600
C19: Foundation | D19: =SUM(E19:P19) -> 4100 | E19: 100 | F19: 800 | G19: 300 | H19: 400 | I19: 500 | J19: 600 | K19: 200 | L19: 100 | M19: 200 | N19: 300 | O19: 400 | P19: 200
C20: Framing | D20: =SUM(E20:P20) -> 3800 | E20: 200 | F20: 100 | G20: 200 | H20: 600 | I20: 400 | J20: 200 | K20: 100 | L20: 200 | M20: 300 | N20: 400 | O20: 500 | P20: 600
C21: Roofing | D21: =SUM(E21:P21) -> 3400 | E21: 100 | F21: 200 | G21: 200 | H21: 400 | I21: 500 | J21: 600 | K21: 200 | L21: 100 | M21: 200 | N21: 300 | O21: 400 | P21: 200
C22: Plumbing | D22: =SUM(E22:P22) -> 3500 | E22: 200 | F22: 100 | G22: 200 | H22: 300 | I22: 400 | J22: 200 | K22: 100 | L22: 200 | M22: 300 | N22: 400 | O22: 500 | P22: 600
C23: Electrical | D23: =SUM(E23:P23) -> 4300 | E23: 200 | F23: 400 | G23: 200 | H23: 300 | I23: 400 | J23: 200 | K23: 100 | L23: 700 | M23: 300 | N23: 400 | O23: 500 | P23: 600
C24: HVAC | D24: =SUM(E24:P24) -> 3500 | E24: 200 | F24: 100 | G24: 200 | H24: 300 | I24: 400 | J24: 200 | K24: 100 | L24: 200 | M24: 300 | N24: 400 | O24: 500 | P24: 600
C25: Insulation | D25: =SUM(E25:P25) -> 3500 | E25: 100 | F25: 200 | G25: 300 | H25: 400 | I25: 500 | J25: 600 | K25: 200 | L25: 100 | M25: 200 | N25: 300 | O25: 400 | P25: 200
C26: Drywall | D26: =SUM(E26:P26) -> 4200 | E26: 200 | F26: 100 | G26: 200 | H26: 300 | I26: 400 | J26: 900 | K26: 100 | L26: 200 | M26: 300 | N26: 400 | O26: 500 | P26: 600
C27: Flooring | D27: =SUM(E27:P27) -> 3500 | E27: 200 | F27: 100 | G27: 200 | H27: 300 | I27: 400 | J27: 200 | K27: 100 | L27: 200 | M27: 300 | N27: 400 | O27: 500 | P27: 600
B29: MATERIALS | C29: Cost Category | D29: TOTAL | E29: 44927 | F29: 44958 | G29: 44986 | H29: 45017 | I29: 45047 | J29: 45078 | K29: 45108 | L29: 45139 | M29: 45170 | N29: 45200 | O29: 45231 | P29: 45261
C30: =C18 -> Excavation | D30: =SUM(E30:P30) -> 4200 | E30: 200 | F30: 100 | G30: 200 | H30: 300 | I30: 400 | J30: 200 | K30: 800 | L30: 200 | M30: 300 | N30: 400 | O30: 500 | P30: 600
C31: =C19 -> Foundation | D31: =SUM(E31:P31) -> 3500 | E31: 100 | F31: 200 | G31: 300 | H31: 400 | I31: 500 | J31: 600 | K31: 200 | L31: 100 | M31: 200 | N31: 300 | O31: 400 | P31: 200
C32: =C20 -> Framing | D32: =SUM(E32:P32) -> 0
C33: =C21 -> Roofing | D33: =SUM(E33:P33) -> 0
C34: =C22 -> Plumbing | D34: =SUM(E34:P34) -> 0
C35: =C23 -> Electrical | D35: =SUM(E35:P35) -> 0
C36: =C24 -> HVAC | D36: =SUM(E36:P36) -> 0
C37: =C25 -> Insulation | D37: =SUM(E37:P37) -> 600 | O37: 400 | P37: 200
C38: =C26 -> Drywall | D38: =SUM(E38:P38) -> 4300 | E38: 1000 | F38: 100 | G38: 200 | H38: 300 | I38: 400 | J38: 200 | K38: 100 | L38: 200 | M38: 300 | N38: 400 | O38: 500 | P38: 600
C39: =C27 -> Flooring | D39: =SUM(E39:P39) -> 3500 | E39: 200 | F39: 100 | G39: 200 | H39: 300 | I39: 400 | J39: 200 | K39: 100 | L39: 200 | M39: 300 | N39: 400 | O39: 500 | P39: 600
B41: EQUIPTMENT | C41: Cost Category | D41: TOTAL | E41: 44927 | F41: 44958 | G41: 44986 | H41: 45017 | I41: 45047 | J41: 45078 | K41: 45108 | L41: 45139 | M41: 45170 | N41: 45200 | O41: 45231 | P41: 45261
C42: =C18 -> Excavation | D42: =SUM(E42:P42) -> 4100 | E42: 200 | F42: 100 | G42: 200 | H42: 300 | I42: 400 | J42: 200 | K42: 700 | L42: 200 | M42: 300 | N42: 400 | O42: 500 | P42: 600
C43: =C19 -> Foundation | D43: =SUM(E43:P43) -> 3500 | E43: 100 | F43: 200 | G43: 300 | H43: 400 | I43: 500 | J43: 600 | K43: 200 | L43: 100 | M43: 200 | N43: 300 | O43: 400 | P43: 200
C44: =C20 -> Framing | D44: =SUM(E44:P44) -> 3500 | E44: 200 | F44: 100 | G44: 200 | H44: 300 | I44: 400 | J44: 200 | K44: 100 | L44: 200 | M44: 300 | N44: 400 | O44: 500 | P44: 600
C45: =C21 -> Roofing | D45: =SUM(E45:P45) -> 4200 | E45: 100 | F45: 200 | G45: 300 | H45: 400 | I45: 500 | J45: 600 | K45: 200 | L45: 800 | M45: 200 | N45: 300 | O45: 400 | P45: 200
C46: =C22 -> Plumbing | D46: =SUM(E46:P46) -> 3500 | E46: 200 | F46: 100 | G46: 200 | H46: 300 | I46: 400 | J46: 200 | K46: 100 | L46: 200 | M46: 300 | N46: 400 | O46: 500 | P46: 600
C47: =C23 -> Electrical | D47: =SUM(E47:P47) -> 3500 | E47: 200 | F47: 100 | G47: 200 | H47: 300 | I47: 400 | J47: 200 | K47: 100 | L47: 200 | M47: 300 | N47: 400 | O47: 500 | P47: 600
C48: =C24 -> HVAC | D48: =SUM(E48:P48) -> 3500 | E48: 200 | F48: 100 | G48: 200 | H48: 300 | I48: 400 | J48: 200 | K48: 100 | L48: 200 | M48: 300 | N48: 400 | O48: 500 | P48: 600
C49: =C25 -> Insulation | D49: =SUM(E49:P49) -> 4300 | E49: 100 | F49: 200 | G49: 300 | H49: 400 | I49: 500 | J49: 600 | K49: 200 | L49: 900 | M49: 200 | N49: 300 | O49: 400 | P49: 200
C50: =C26 -> Drywall | D50: =SUM(E50:P50) -> 3500 | E50: 200 | F50: 100 | G50: 200 | H50: 300 | I50: 400 | J50: 200 | K50: 100 | L50: 200 | M50: 300 | N50: 400 | O50: 500 | P50: 600
...

Sheet CashFlow Projection
B2: Cash Flow Projection
G4: CASH INFLOW | L4: CASH OUTFLOW
B5: Date Prepared | C5: 47721
B7: Prepared by | C7: John Mitchell
B9: For the Year | C9: =C5 -> 47721
B11: CASH FLOW | C11: {=TRANSPOSE(B18:B27)} -> Rental | D11: Personal Funds | E11: Loans | F11: Investment | G11: Personal Saving | H11: 0 | I11: 0 | J11: 0 | K11: 0 | L11: 0 | N11: CASH FLOW IN TOTAL
B12: IN | C12: {=TRANSPOSE(C18:C27)} -> 4200 | D12: 3500 | E12: 4100 | F12: 4300 | G12: 3500 | H12: 0 | I12: 0 | J12: 0 | K12: 0 | L12: 0 | N12: =SUM(C12:M12) -> 19600
B13: CASH FLOW | C13: {=TRANSPOSE(B30:B39)} -> Materials | D13: Labor Cost | E13: Permits & Fees | F13: Equiptment & Tools | G13: Utilities | H13: Insurance | I13: Professional Services | J13: Marketing & Advertisment | K13: Contingency | L13: Other Expenses | N13: CASH FLOW OUT TOTAL
B14: OUT | C14: {=TRANSPOSE(C30:C39)} -> 4200 | D14: 3500 | E14: 4100 | F14: 4300 | G14: 3500 | H14: 3500 | I14: 3500 | J14: 3500 | K14: 3500 | L14: 3500 | N14: =SUM(C14:M14) -> 37100
B17: IN | C17: TOTAL | D17: 44927 | E17: 44958 | F17: 44986 | G17: 45017 | H17: 45047 | I17: 45078 | J17: 45108 | K17: 45139 | L17: 45170 | M17: 45200 | N17: 45231 | O17: 45261
B18: Rental | C18: =SUM(D18:O18) -> 4200 | D18: 200 | E18: 100 | F18: 200 | G18: 300 | H18: 400 | I18: 200 | J18: 800 | K18: 200 | L18: 300 | M18: 400 | N18: 500 | O18: 600
B19: Personal Funds | C19: =SUM(D19:O19) -> 3500 | D19: 100 | E19: 200 | F19: 300 | G19: 400 | H19: 500 | I19: 600 | J19: 200 | K19: 100 | L19: 200 | M19: 300 | N19: 400 | O19: 200
B20: Loans | C20: =SUM(D20:O20) -> 4100 | D20: 200 | E20: 100 | F20: 200 | G20: 300 | H20: 400 | I20: 200 | J20: 700 | K20: 200 | L20: 300 | M20: 400 | N20: 500 | O20: 600
B21: Investment | C21: =SUM(D21:O21) -> 4300 | D21: 900 | E21: 200 | F21: 300 | G21: 400 | H21: 500 | I21: 600 | J21: 200 | K21: 100 | L21: 200 | M21: 300 | N21: 400 | O21: 200
B22: Personal Saving | C22: =SUM(D22:O22) -> 3500 | D22: 200 | E22: 100 | F22: 200 | G22: 300 | H22: 400 | I22: 200 | J22: 100 | K22: 200 | L22: 300 | M22: 400 | N22: 500 | O22: 600
B29: OUT | C29: TOTAL | D29: 44927 | E29: 44958 | F29: 44986 | G29: 45017 | H29: 45047 | I29: 45078 | J29: 45108 | K29: 45139 | L29: 45170 | M29: 45200 | N29: 45231 | O29: 45261
B30: Materials | C30: =SUM(D30:O30) -> 4200 | D30: 200 | E30: 100 | F30: 200 | G30: 300 | H30: 400 | I30: 200 | J30: 800 | K30: 200 | L30: 300 | M30: 400 | N30: 500 | O30: 600
B31: Labor Cost | C31: =SUM(D31:O31) -> 3500 | D31: 100 | E31: 200 | F31: 300 | G31: 400 | H31: 500 | I31: 600 | J31: 200 | K31: 100 | L31: 200 | M31: 300 | N31: 400 | O31: 200
B32: Permits & Fees | C32: =SUM(D32:O32) -> 4100 | D32: 200 | E32: 100 | F32: 200 | G32: 300 | H32: 400 | I32: 200 | J32: 700 | K32: 200 | L32: 300 | M32: 400 | N32: 500 | O32: 600
B33: Equiptment & Tools | C33: =SUM(D33:O33) -> 4300 | D33: 900 | E33: 200 | F33: 300 | G33: 400 | H33: 500 | I33: 600 | J33: 200 | K33: 100 | L33: 200 | M33: 300 | N33: 400 | O33: 200
B34: Utilities | C34: =SUM(D34:O34) -> 3500 | D34: 200 | E34: 100 | F34: 200 | G34: 300 | H34: 400 | I34: 200 | J34: 100 | K34: 200 | L34: 300 | M34: 400 | N34: 500 | O34: 600
B35: Insurance | C35: =SUM(D35:O35) -> 3500 | D35: 200 | E35: 100 | F35: 200 | G35: 300 | H35: 400 | I35: 200 | J35: 100 | K35: 200 | L35: 300 | M35: 400 | N35: 500 | O35: 600
B36: Professional Services | C36: =SUM(D36:O36) -> 3500 | D36: 200 | E36: 100 | F36: 200 | G36: 300 | H36: 400 | I36: 200 | J36: 100 | K36: 200 | L36: 300 | M36: 400 | N36: 500 | O36: 600
B37: Marketing & Advertisment | C37: =SUM(D37:O37) -> 3500 | D37: 100 | E37: 200 | F37: 300 | G37: 400 | H37: 500 | I37: 600 | J37: 200 | K37: 100 | L37: 200 | M37: 300 | N37: 400 | O37: 200
B38: Contingency | C38: =SUM(D38:O38) -> 3500 | D38: 200 | E38: 100 | F38: 200 | G38: 300 | H38: 400 | I38: 200 | J38: 100 | K38: 200 | L38: 300 | M38: 400 | N38: 500 | O38: 600
B39: Other Expenses | C39: =SUM(D39:O39) -> 3500 | D39: 200 | E39: 100 | F39: 200 | G39: 300 | H39: 400 | I39: 200 | J39: 100 | K39: 200 | L39: 300 | M39: 400 | N39: 500 | O39: 600

Sheet Instructions
B23: The following are instructions on how to use the template.
B25: 1. Edit or add content like inserting rows and columns to the template.
B26: 2. There are no locked-up cells for easier editing of cell names.
B27: 3. Feel free to change any formula available.
B29: Should you need assistance, please contact our Customer Support Team using the chat box found on the website.
