Workbook

Sheet Balance Sheet Projection
D2: BALANCE SHEET PROJECTION
B5: ASSETS | E5: 2019 | F5: 2020 | G5: 2021 | H5: 2022 | I5: 2023
B6: CURRENT ASSETS
B7: Cash and Cash Equivalents | E7: 250000 | F7: 300000 | G7: 400000 | H7: 500000 | I7: 500000
B8: Accounts Receivable | E8: 850000 | F8: 900000 | G8: 650000 | H8: 700000 | I8: 800000
B9: Less: Allowance for Doubtful Accounts | E9: -50000 | F9: -60000 | G9: -50000 | H9: -60000 | I9: -60000
B10: Inventory | E10: 1200000 | F10: 1150000 | G10: 1200000 | H10: 1150000 | I10: 1150000
B11: Prepaid Expenses | E11: 30000 | F11: 35000 | G11: 30000 | H11: 35000 | I11: 35000
B12: TOTAL CURRENT ASSETS | E12: =SUM(E7:E11) -> 2280000 | F12: =SUM(F7:F11) -> 2325000 | G12: =SUM(G7:G11) -> 2230000 | H12: =SUM(H7:H11) -> 2325000 | I12: =SUM(I7:I11) -> 2425000
B14: PROPERTY, PLANT, AND EQUIPMENT (PPE)
B15: Land | E15: 500000 | F15: 500000 | G15: 500000 | H15: 500000 | I15: 500000
B16: Buildings | E16: 2000000 | F16: 1000000 | G16: 2000000 | H16: 2000000 | I16: 2000000
B17: Construction Equipment | E17: 3500000 | F17: 3800000 | G17: 4000000 | H17: 3800000 | I17: 3800000
B18: Less: Accumulated Depreciation | E18: -1200000 | F18: -1400000 | G18: -1200000 | H18: -1400000 | I18: -1400000
B19: Vehicles | E19: 350000 | F19: 400000 | G19: 350000 | H19: 500000 | I19: 400000
B20: Less: Accumulated Depreciation | E20: -120000 | F20: -150000 | G20: -120000 | H20: -150000 | I20: -150000
B21: TOTAL PPE | E21: =SUM(E15:E20) -> 5030000 | F21: =SUM(F15:F20) -> 4150000 | G21: =SUM(G15:G20) -> 5530000 | H21: =SUM(H15:H20) -> 5250000 | I21: =SUM(I15:I20) -> 5150000
B23: OTHER LONG TERM ASSETS
B24: Investments | E24: 300000 | F24: 250000 | G24: 200000 | H24: 350000 | I24: 450000
B25: Intangible Assets | E25: 50000 | F25: 50000 | G25: 50000 | H25: 100000 | I25: 50000
B26: Less: Accumulated Amortization | E26: -10000 | F26: -12000 | G26: -10000 | H26: -12000 | I26: -12000
B27: TOTAL OTHER LONG TERM ASSETS | E27: =SUM(E24:E26) -> 340000 | F27: =SUM(F24:F26) -> 288000 | G27: =SUM(G24:G26) -> 240000 | H27: =SUM(H24:H26) -> 438000 | I27: =SUM(I24:I26) -> 488000
B29: TOTAL ASSETS | E29: =E12+E21+E27 -> 7650000 | F29: =F12+F21+F27 -> 6763000 | G29: =G12+G21+G27 -> 8000000 | H29: =H12+H21+H27 -> 8013000 | I29: =I12+I21+I27 -> 8063000
B31: LIABILITIES AND SHAREHOLDER'S EQUITY | E31: 2019 | F31: 2020 | G31: 2021 | H31: 2022 | I31: 2023
B33: CURRENT LIABILITIES
B34: Accounts Payable | E34: 500000 | F34: 600000 | G34: 500000 | H34: 600000 | I34: 600000
B35: Accrued Expenses | E35: 250000 | F35: 275000 | G35: 250000 | H35: 275000 | I35: 275000
B36: Short-Term Loans | E36: 150000 | F36: 100000 | G36: 150000 | H36: 100000 | I36: 100000
B37: TOTAL CURRENT LIABILITIES | E37: =SUM(E34:E36) -> 900000 | F37: =SUM(F34:F36) -> 975000 | G37: =SUM(G34:G36) -> 900000 | H37: =SUM(H34:H36) -> 975000 | I37: =SUM(I34:I36) -> 975000
B39: LONG-TERM LIABILITIES
B40: Long-Term Debt | E40: 3000000 | F40: 2250000 | G40: 3000000 | H40: 3100000 | I40: 3200000
B41: Lease Obligations | E41: 300000 | F41: 250000 | G41: 300000 | H41: 250000 | I41: 250000
B42: TOTAL LONG-TERM LIABILITIES | E42: =SUM(E40:E41) -> 3300000 | F42: =SUM(F40:F41) -> 2500000 | G42: =SUM(G40:G41) -> 3300000 | H42: =SUM(H40:H41) -> 3350000 | I42: =SUM(I40:I41) -> 3450000
B44: SHAREHOLDER'S EQUITY
B45: Common Stock | E45: 900000 | F45: 900000 | G45: 1000000 | H45: 500000 | I45: 400000
B46: Preferred Stock | E46: 100000 | F46: 100000 | G46: 250000 | H46: 100000 | I46: 250000
B47: Additional Paid-in Capital | E47: 750000 | F47: 750000 | G47: 750000 | H47: 750000 | I47: 750000
B48: Retained Earnings | E48: 1500000 | F48: 2438000 | G48: 1900000 | H48: 2438000 | I48: 2438000
B49: TOTAL SHAREHOLDER'S EQUITY | E49: =SUM(E45:E48) -> 3250000 | F49: =SUM(F45:F48) -> 4188000 | G49: =SUM(G45:G48) -> 3900000 | H49: =SUM(H45:H48) -> 3788000 | I49: =SUM(I45:I48) -> 3838000
B51: TOTAL LIABILITIES AND SHAREHOLDER'S EQUITY | E51: =E37+E42+E49 -> 7450000 | F51: =F37+F42+F49 -> 7663000 | G51: =G37+G42+G49 -> 8100000 | H51: =H37+H42+H49 -> 8113000 | I51: =I37+I42+I49 -> 8263000
...

Sheet Dashboard
C2: Chicago, IL 60631 | D2: DASHBOARD
C3: info@construct.com
C4: construct.com
C5: 222 555 7777
B7: TOTAL ASSETS
B8: {='Chart Support'!N3:N4} -> 2019
B9: 7650000
B10: {='Chart Support'!O3:O4} -> 2020
B11: 6763000
B12: {='Chart Support'!P3:P4} -> 2021
B13: 8000000
B14: {='Chart Support'!Q3:Q4} -> 2022
B15: 8013000
B16: {='Chart Support'!R3:R4} -> 2023
B17: 8063000
B29: TOTAL LIABILITIES
B30: {='Chart Support'!N13:N14} -> 2019
B31: 7450000
B32: {='Chart Support'!O13:O14} -> 2020
B33: 7663000
B34: {='Chart Support'!P13:P14} -> 2021
B35: 8100000
B36: {='Chart Support'!Q13:Q14} -> 2022
B37: 8113000
B38: {='Chart Support'!R13:R14} -> 2023
B39: 8263000

Sheet Instructions
B22: The following are instructions on how to use the template.
B24: 1. There are no locked-up cells for easier editing of cell names.
B25: 2. You can insert/add new notes by inserting another cell.
B26: 3. Icons and images can be replaced by deleting and then inserting new image/s.
B27: 4. Feel free to change any cell/ formula.
B29: Should you need assistance, please contact our Customer Support Team using the chat box found on the website.

Sheet Chart Support
B3: CURRENT ASSETS | N3: 2019 | O3: 2020 | P3: 2021 | Q3: 2022 | R3: 2023
E4: 2019 | F4: 2020 | G4: 2021 | H4: 2022 | I4: 2023 | K4: {='Balance Sheet Projection'!B29:I29} -> TOTAL ASSETS | L4: 0 | M4: 0 | N4: 7650000 | O4: 6763000 | P4: 8000000 | Q4: 8013000 | R4: 8063000
B5: {='Balance Sheet Projection'!B12:I12} -> TOTAL CURRENT ASSETS | C5: 0 | D5: 0 | E5: 2280000 | F5: 2325000 | G5: 2230000 | H5: 2325000 | I5: 2425000
E7: 2019 | F7: 2020 | G7: 2021 | H7: 2022 | I7: 2023
B8: {='Balance Sheet Projection'!B21:I21} -> TOTAL PPE | C8: 0 | D8: 0 | E8: 5030000 | F8: 4150000 | G8: 5530000 | H8: 5250000 | I8: 5150000
E10: 2019 | F10: 2020 | G10: 2021 | H10: 2022 | I10: 2023
B11: {='Balance Sheet Projection'!B27:I27} -> TOTAL OTHER LONG TERM ASSETS | C11: 0 | D11: 0 | E11: 340000 | F11: 288000 | G11: 240000 | H11: 438000 | I11: 488000
N13: 2019 | O13: 2020 | P13: 2021 | Q13: 2022 | R13: 2023
K14: {='Balance Sheet Projection'!B51:I51} -> TOTAL LIABILITIES AND SHAREHOLDER'S EQUITY | L14: 0 | M14: 0 | N14: 7450000 | O14: 7663000 | P14: 8100000 | Q14: 8113000 | R14: 8263000
E15: 2019 | F15: 2020 | G15: 2021 | H15: 2022 | I15: 2023
B16: {='Balance Sheet Projection'!B37:I37} -> TOTAL CURRENT LIABILITIES | C16: 0 | D16: 0 | E16: 900000 | F16: 975000 | G16: 900000 | H16: 975000 | I16: 975000
E18: 2019 | F18: 2020 | G18: 2021 | H18: 2022 | I18: 2023
B19: {='Balance Sheet Projection'!B42:I42} -> TOTAL LONG-TERM LIABILITIES | C19: 0 | D19: 0 | E19: 3300000 | F19: 2500000 | G19: 3300000 | H19: 3350000 | I19: 3450000
E21: 2019 | F21: 2020 | G21: 2021 | H21: 2022 | I21: 2023
B22: {='Balance Sheet Projection'!B49:I49} -> TOTAL SHAREHOLDER'S EQUITY | C22: 0 | D22: 0 | E22: 3250000 | F22: 4188000 | G22: 3900000 | H22: 3788000 | I22: 3838000
